2025-10-29 15:46:48,851 ERROR: Exception on /favicon.ico [GET] [in C:\Users\windows\AppData\Roaming\Python\Python313\site-packages\flask\app.py:875]
Traceback (most recent call last):
  File "C:\Users\windows\AppData\Roaming\Python\Python313\site-packages\sqlalchemy\engine\base.py", line 1963, in _exec_single_context
    self.dialect.do_execute(
    ~~~~~~~~~~~~~~~~~~~~~~~^
        cursor, str_statement, effective_parameters, context
        ^^^^^^^^^^^^^^^^^^^^^^^^^^^^^^^^^^^^^^^^^^^^^^^^^^^^
    )
    ^
  File "C:\Users\windows\AppData\Roaming\Python\Python313\site-packages\sqlalchemy\engine\default.py", line 943, in do_execute
    cursor.execute(statement, parameters)
    ~~~~~~~~~~~~~~^^^^^^^^^^^^^^^^^^^^^^^
sqlite3.OperationalError: no such table: maintenance_settings

The above exception was the direct cause of the following exception:

Traceback (most recent call last):
  File "C:\Users\windows\AppData\Roaming\Python\Python313\site-packages\flask\app.py", line 1511, in wsgi_app
    response = self.full_dispatch_request()
  File "C:\Users\windows\AppData\Roaming\Python\Python313\site-packages\flask\app.py", line 919, in full_dispatch_request
    rv = self.handle_user_exception(e)
  File "C:\Users\windows\AppData\Roaming\Python\Python313\site-packages\flask\app.py", line 915, in full_dispatch_request
    rv = self.preprocess_request()
  File "C:\Users\windows\AppData\Roaming\Python\Python313\site-packages\flask\app.py", line 1291, in preprocess_request
    rv = self.ensure_sync(before_func)()
  File "e:\KreasiX\kreasiPOS\app\__init__.py", line 102, in check_maintenance
    if MaintenanceService.is_maintenance_mode():
       ~~~~~~~~~~~~~~~~~~~~~~~~~~~~~~~~~~~~~~^^
  File "e:\KreasiX\kreasiPOS\app\services\maintenance_service.py", line 18, in is_maintenance_mode
    settings = MaintenanceService.get_settings()
  File "e:\KreasiX\kreasiPOS\app\services\maintenance_service.py", line 8, in get_settings
    settings = MaintenanceSettings.query.first()
  File "C:\Users\windows\AppData\Roaming\Python\Python313\site-packages\sqlalchemy\orm\query.py", line 2759, in first
    return self.limit(1)._iter().first()  # type: ignore
           ~~~~~~~~~~~~~~~~~~~^^
  File "C:\Users\windows\AppData\Roaming\Python\Python313\site-packages\sqlalchemy\orm\query.py", line 2857, in _iter
    result: Union[ScalarResult[_T], Result[_T]] = self.session.execute(
                                                  ~~~~~~~~~~~~~~~~~~~~^
        statement,
        ^^^^^^^^^^
        params,
        ^^^^^^^
        execution_options={"_sa_orm_load_options": self.load_options},
        ^^^^^^^^^^^^^^^^^^^^^^^^^^^^^^^^^^^^^^^^^^^^^^^^^^^^^^^^^^^^^^
    )
    ^
  File "C:\Users\windows\AppData\Roaming\Python\Python313\site-packages\sqlalchemy\orm\session.py", line 2365, in execute
    return self._execute_internal(
           ~~~~~~~~~~~~~~~~~~~~~~^
        statement,
        ^^^^^^^^^^
    ...<4 lines>...
        _add_event=_add_event,
        ^^^^^^^^^^^^^^^^^^^^^^
    )
    ^
  File "C:\Users\windows\AppData\Roaming\Python\Python313\site-packages\sqlalchemy\orm\session.py", line 2251, in _execute_internal
    result: Result[Any] = compile_state_cls.orm_execute_statement(
                          ~~~~~~~~~~~~~~~~~~~~~~~~~~~~~~~~~~~~~~~^
        self,
        ^^^^^
    ...<4 lines>...
        conn,
        ^^^^^
    )
    ^
  File "C:\Users\windows\AppData\Roaming\Python\Python313\site-packages\sqlalchemy\orm\context.py", line 306, in orm_execute_statement
    result = conn.execute(
        statement, params or {}, execution_options=execution_options
    )
  File "C:\Users\windows\AppData\Roaming\Python\Python313\site-packages\sqlalchemy\engine\base.py", line 1415, in execute
    return meth(
        self,
        distilled_parameters,
        execution_options or NO_OPTIONS,
    )
  File "C:\Users\windows\AppData\Roaming\Python\Python313\site-packages\sqlalchemy\sql\elements.py", line 523, in _execute_on_connection
    return connection._execute_clauseelement(
           ~~~~~~~~~~~~~~~~~~~~~~~~~~~~~~~~~^
        self, distilled_params, execution_options
        ^^^^^^^^^^^^^^^^^^^^^^^^^^^^^^^^^^^^^^^^^
    )
    ^
  File "C:\Users\windows\AppData\Roaming\Python\Python313\site-packages\sqlalchemy\engine\base.py", line 1637, in _execute_clauseelement
    ret = self._execute_context(
        dialect,
    ...<8 lines>...
        cache_hit=cache_hit,
    )
  File "C:\Users\windows\AppData\Roaming\Python\Python313\site-packages\sqlalchemy\engine\base.py", line 1842, in _execute_context
    return self._exec_single_context(
           ~~~~~~~~~~~~~~~~~~~~~~~~~^
        dialect, context, statement, parameters
        ^^^^^^^^^^^^^^^^^^^^^^^^^^^^^^^^^^^^^^^
    )
    ^
  File "C:\Users\windows\AppData\Roaming\Python\Python313\site-packages\sqlalchemy\engine\base.py", line 1982, in _exec_single_context
    self._handle_dbapi_exception(
    ~~~~~~~~~~~~~~~~~~~~~~~~~~~~^
        e, str_statement, effective_parameters, cursor, context
        ^^^^^^^^^^^^^^^^^^^^^^^^^^^^^^^^^^^^^^^^^^^^^^^^^^^^^^^
    )
    ^
  File "C:\Users\windows\AppData\Roaming\Python\Python313\site-packages\sqlalchemy\engine\base.py", line 2351, in _handle_dbapi_exception
    raise sqlalchemy_exception.with_traceback(exc_info[2]) from e
  File "C:\Users\windows\AppData\Roaming\Python\Python313\site-packages\sqlalchemy\engine\base.py", line 1963, in _exec_single_context
    self.dialect.do_execute(
    ~~~~~~~~~~~~~~~~~~~~~~~^
        cursor, str_statement, effective_parameters, context
        ^^^^^^^^^^^^^^^^^^^^^^^^^^^^^^^^^^^^^^^^^^^^^^^^^^^^
    )
    ^
  File "C:\Users\windows\AppData\Roaming\Python\Python313\site-packages\sqlalchemy\engine\default.py", line 943, in do_execute
    cursor.execute(statement, parameters)
    ~~~~~~~~~~~~~~^^^^^^^^^^^^^^^^^^^^^^^
sqlalchemy.exc.OperationalError: (sqlite3.OperationalError) no such table: maintenance_settings
[SQL: SELECT maintenance_settings.id AS maintenance_settings_id, maintenance_settings.is_active AS maintenance_settings_is_active, maintenance_settings.message AS maintenance_settings_message, maintenance_settings.start_time AS maintenance_settings_start_time, maintenance_settings.estimated_end_time AS maintenance_settings_estimated_end_time, maintenance_settings.allowed_emails AS maintenance_settings_allowed_emails, maintenance_settings.created_at AS maintenance_settings_created_at, maintenance_settings.updated_at AS maintenance_settings_updated_at 
FROM maintenance_settings
 LIMIT ? OFFSET ?]
[parameters: (1, 0)]
(Background on this error at: https://sqlalche.me/e/20/e3q8)
2025-10-29 15:49:06,728 INFO: POS RSS startup [in e:\KreasiX\kreasiPOS\app\__init__.py:160]
